Workbook

Sheet 📋 Instructions
B1: SkinB5 Growth 2026 — Master KPI Tracker | Weekly Update Guide for Digital Marketing Specialist
B2: 🔵 Blue = your input ⚫ Black = auto-calculated 🟡 Yellow highlight = must update this week Update every Monday by 8:45am AEST
B4: COLOUR LEGEND
B5: Sample | C5: Blue text on yellow = INPUT CELL — type your number here
B6: Sample | C6: Blue text on white = input cell (non-urgent)
B7: Sample | C7: Black text = formula auto-calculates — DO NOT type here
B8: Sample | C8: Green text = pulled from another sheet automatically
B9: Sample | C9: Red background = behind target — needs attention
B10: Sample | C10: Gold background = watch — approaching risk
B12: STEP-BY-STEP — EVERY MONDAY MORNING
B13: Step 1: Open this file | C13: Always use the latest version from Google Drive. Check the filename date. | E13: ⏱ 5 min
B14: Step 2: Go to 🛒 Shopify (Auto) | C14: This sheet MOSTLY auto-fills if Shopify is connected. Check that totals look right. Add any manual overrides in blue cells. | E14: ⏱ 5 min
B15: Step 3: Go to 📧 Email & CRM | C15: Log into Klaviyo. Pull: list size, welcome flow CVR, win-back CVR, campaign open rates. Enter in blue cells. | E15: ⏱ 10 min
B16: Step 4: Go to 📱 Social Media | C16: Log into TikTok Business Centre + Meta Business Suite + GA4. Pull weekly figures for each platform. | E16: ⏱ 10 min
B17: Step 5: Go to 🏥 Clinic Pipeline | C17: Update how many clinics were pitched, meetings booked, and closed this week. Comes from your own outreach log. | E17: ⏱ 5 min
B18: Step 6: Go to 🌏 Asia Sales | C18: Enter China MTD sales + days elapsed. Enter South Korea monthly sales. Convert to AUD first using xe.com. | E18: ⏱ 5 min
B19: Step 7: Go to 💰 Paid Ads | C19: Log into Meta Ads Manager, TikTok Ads Manager, AND Google Ads (ads.google.com). Pull spend, ROAS, CPC, and CAC for all three platforms. | E19: ⏱ 5 min
B20: Step 8: Check 📊 Dashboard Summary | C20: Glance at the summary tab. If anything shows red or is blank, go back and fix. Save + share with founder. | E20: ⏱ 2 min
B22: TOTAL TIME REQUIRED EACH MONDAY | E22: ~45 minutes

Sheet 🛒 Shopify & Revenue
B1: Shopify & Revenue — Weekly KPI Log | 90-Day Sprint
B2: KPI Metric | C2: Data Source | D2: W1 | E2: W2 | F2: W3 | G2: W4 | H2: W5 | I2: W6 | J2: W7 | K2: W8 | L2: W9 | M2: W10 | N2: W11 | O2: W12 | P2: W13 | Q2: 90d Target | R2: Latest Status
B3: 💰 REVENUE — Pull from Shopify Analytics every Monday
B4: Weekly revenue (AUD) | C4: Shopify Analytics | D4: 2467.76 | E4: 2161.49 | F4: 2124.79 | G4: 2676.18 | H4: 2152.22 | I4: 2681.1 | J4: 2370.85 | K4: 3827.56 | L4: 2819.82 | M4: 2888.61 | Q4: $5,500/wk by W13 | R4: → Update weekly
B5: Monthly revenue MTD (AUD) | C5: Shopify Analytics | D5: 2467.76 | E5: 4629.25 | F5: 6754.04 | G5: 10048.76 | H5: 2152.22 | I5: 4833.32 | J5: 7808.83 | K5: 11401.02 | L5: 2819.82 | M5: 5459.68 | Q5: $22,000/mo by Day 90 | R5: → Update weekly
B6: Number of orders (week) | C6: Shopify Analytics | D6: 35 | E6: 31 | F6: 36 | G6: 28 | H6: 31 | I6: 45 | J6: 34 | K6: 49 | L6: 42 | M6: 38 | Q6: Track trend | R6: → Update weekly
B7: Average order value — AOV (AUD) | C7: Shopify Analytics → Reports | D7: 70.51 | E7: 69.73 | F7: 59.02 | G7: 92.28 | H7: 59.76 | I7: 50.11 | J7: 61.04 | K7: 67.06 | L7: 61.95 | M7: 64.84 | Q7: Target +15% vs baseline | R7: → Update weekly
B8: New customer revenue (AUD) | C8: Shopify Customers report | D8: 1855.79 | E8: $866.25 | F8: $719.38 | G8: 966.33 | H8: 945.12 | I8: 1151.5 | J8: 802.74 | K8: 1423.91 | L8: 638.6 | M8: 1515.24 | Q8: Track vs returning | R8: → Update weekly
B9: Returning customer revenue (AUD) | C9: Shopify Customers report | D9: 1228.18 | E9: $1673.97 | F9: $1574.95 | G9: 1709.85 | H9: 1207.1 | I9: 1529.6 | J9: 1568.11 | K9: 2403.65 | L9: $2,09.38 | M9: 1373.37 | Q9: Target >50% of total | R9: → Update weekly
B11: 👥 CUSTOMER METRICS — Pull from Shopify Analytics → Customers
B12: New customers this week | C12: Shopify → Customers | D12: 19 | E12: 12 | F12: 11 | G12: 11 | H12: 13 | I12: 25 | J12: 14 | K12: 20 | L12: 13 | M12: 13 | Q12: Track trend | R12: → Update weekly
B13: Returning customers this week | C13: Shopify → Customers | D13: 17 | E13: 18 | F13: 23 | G13: 18 | H13: 17 | I13: 20 | J13: 20 | K13: 30 | L13: 28 | M13: 20 | Q13: Track trend | R13: → Update weekly
B14: Repeat purchase rate (%) | C14: Shopify → Customers → Returning rate | D14: 0.49 | E14: 0.6 | F14: 0.6618 | G14: 0.6207 | H14: 0.5657 | I14: 0.4444 | J14: 0.5882 | K14: 0.6 | L14: 0.69 | M14: 0.6 | Q14: >35% | R14: → Update weekly
B15: Customer lifetime value — LTV (AUD) | C15: Shopify → Customers → LTV report | D15: 2144 | E15: 433.46 | F15: 879.14 | G15: 999.13 | H15: 1148.58 | I15: 1457.75 | J15: 672.76 | K15: 1448.64 | L15: 638.6 | M15: 1449 | Q15: +20% over 90 days | R15: → Update weekly
B16: Churn rate — % customers not re-buying | C16: Shopify / manual calc | D16: 0.91 | E16: 0.4 | F16: 0.3382 | G16: 0.38 | H16: 56%% | I16: 0.5224 | J16: 0.522 | K16: 0.55 | L16: 0.317 | M16: 0.55 | Q16: <30% | R16: → Update weekly
B17: Total active customers (cumulative) | C17: Shopify → Customers | D17: 6086 | E17: 6098 | F17: 6109 | G17: 6126 | H17: 6501 | I17: 6501 | J17: 6515 | K17: 6538 | L17: 6551 | M17: 6538 | Q17: Track trend | R17: → Update weekly
B19: 🛒 CONVERSION — Pull from Shopify Analytics → Online Store
B20: Online store sessions (week) | C20: Shopify Analytics → Sessions | D20: 1297 | E20: 1329 | F20: 1461 | G20: 2200 | H20: 3454 | I20: 6652 | J20: 2452 | K20: 2644 | L20: 1653 | M20: 1314 | Q20: 2,000+ new/wk | R20: → Update weekly
B21: Store conversion rate (%) | C21: Shopify Analytics → Sessions | D21: 0.0177 | E21: 0.0173 | F21: 0.0178 | G21: 0.01 | H21: 0.007 | I21: 0.0044 | J21: 0.0098 | K21: 0.0238 | L21: 0.0169 | M21: 0.0244 | Q21: >2.5% | R21: → Update weekly
B22: Add to cart rate (%) | C22: Shopify Analytics → Behaviour | D22: 0.0547 | E22: 0.0459 | F22: 0.0486 | G22: 0.0282 | H22: 0.0171 | I22: 0.0107 | J22: 0.0232 | K22: 0.0238 | L22: 0.0375 | M22: 0.0426 | Q22: >8% | R22: → Update weekly
B23: Checkout completion rate (%) | C23: Shopify Analytics → Behaviour | D23: 0.3026 | E23: 0.377 | F23: 0.3824 | G23: 0.4 | H23: 0.3333 | I23: 0.4028 | J23: 0.4889 | K23: 0.4382 | L23: 0.549 | M23: 0.6444 | Q23: >65% | R23: → Update weekly
B24: Cart abandonment rate (%) | C24: Shopify / Klaviyo | D24: 0.6974 | E24: 0.623 | F24: 0.6176 | G24: 0.6 | H24: 0.6667 | I24: 0.5972 | J24: 0.6522 | K24: 0.56 | L24: 0.5484 | M24: 0.3929 | Q24: <35% | R24: → Update weekly

Sheet 📧 Email & CRM
B1: Email & CRM — Weekly KPI Log | 90-Day Sprint
B2: KPI Metric | C2: Data Source | D2: W1 | E2: W2 | F2: W3 | G2: W4 | H2: W5 | I2: W6 | J2: W7 | K2: W8 | L2: W9 | M2: W10 | N2: W11 | O2: W12 | P2: W13 | Q2: 90d Target | R2: Latest Status
B3: 📧 EMAIL LIST — Pull from instant → Audience
B4: Total email subscribers | C4: Shopify → Lists & Segments | D4: 22840 | E4: 22840 | F4: 22840 | G4: 22840 | H4: 5757 | I4: 6055 | J4: 6022 | K4: 5929 | L4: 5953 | M4: 5901 | Q4: Grow weekly | R4: → Update weekly
B5: Active / engaged subscribers | C5: Klaviyo → Segments → Engaged 90d | I5: 553 | J5: 653 | K5: 772 | L5: 330 | M5: 1855 | Q5: Track % | R5: → Update weekly
B6: New subscribers added this week | C6: Klaviyo → Growth report | I6: 52 | J6: 25 | K6: 34 | L6: 24 | M6: 36 | Q6: +50/wk | R6: → Update weekly
B7: Unsubscribe Shoppers % | C7: Klaviyo → Campaign metrics | Q7: <0.2% | R7: → Update weekly
B9: 💌 FLOWS PERFORMANCE — Pull from Instant → Flows
B10: Welcome series — emails sent | C10: Instant → Flows → Welcome | D10: 41 | E10: 28 | F10: 33164 | G10: 45 | H10: 20 | I10: 25 | J10: 35 | K10: 41 | L10: 35 | M10: 52 | Q10: — | R10: → Update weekly
B11: Welcome series — open rate (%) | C11: Instant → Flows → Welcome | D11: 0.195 | E11: 35.7 | F11: 0.135 | G11: 11.956 | H11: 4.55 | I11: 1.88 | J11: 0.571 | K11: 0.463 | L11: 0.343 | M11: 0.596 | Q11: >35% | R11: → Update weekly
B12: Welcome series — click rate (%) | C12: Instant → Flows → Welcome | D12: 0.0241 | E12: 0.036 | F12: 0.004 | G12: 0.133 | H12: 0.1 | I12: 0.04 | J12: 0 | K12: 0.073 | L12: 0.057 | M12: 0.077 | Q12: >5% | R12: → Update weekly
B13: Welcome series — CVR / purchase rate (%) | C13: Instant→ Flows → Welcome → Placed Order | D13: 0.024 | E13: 0 | F13: 0.01 | G13: 0.067 | H13: 0.05 | I13: 0.04 | J13: 0.029 | K13: 0.024 | L13: 0.029 | M13: 0 | Q13: >3% | R13: → Update weekly
B14: Welcome series — revenue generated (AUD) | C14: Instant → Flows → Welcome → Revenue | D14: 0 | E14: 0 | F14: 39.95 | G14: 321.97 | H14: 73.86 | I14: 143.76 | J14: 41.86 | K14: 89.86 | L14: 49 | M14: 0 | Q14: Track vs $85K 90d target | R14: → Update weekly
B15: Win-back flow — emails sent | C15: Instant → Flows → Win-back | D15: 35 | E15: 66 | F15: 37 | G15: 31 | H15: 302 | I15: 69 | J15: 72 | K15: 53 | L15: 74 | M15: 61 | Q15: — | R15: → Update weekly
B16: Win-back flow — open rate (%) | C16: Instant→ Flows → Win-back | D16: 0.143 | E16: 0.333 | F16: 0.351 | G16: 0.258 | H16: 0.318 | I16: 0.145 | J16: 0.306 | K16: 0.28 | L16: 0.081 | M16: 0.262 | Q16: >28% | R16: → Update weekly
B17: Win-back flow — CVR / purchase rate (%) | C17: Instant → Flows → Win-back → Placed Order | D17: 0 | E17: 0.015 | F17: 0.027 | G17: 0.032 | H17: 0.013 | I17: 0.014 | J17: 0.014 | K17: 0.019 | L17: 0 | M17: 0.016 | Q17: >8% | R17: → Update weekly
B18: Win-back flow — revenue generated (AUD) | C18: Instant → Flows → Win-back → Revenue | D18: 0 | E18: 64.9 | F18: 130.83 | G18: 0 | H18: 200.52 | I18: 43.86 | J18: 56.95 | K18: 58.31 | L18: 0 | M18: 0 | Q18: Track vs $42K 90d target | R18: → Update weekly
B19: Abandoned cart flow — recovery rate (%) | C19: Instant → Flows → Abandoned Cart | H19: 3.3 | I19: 0 | J19: 0 | K19: 5.,3% | L19: 0 | M19: 0.5 | Q19: >15% | R19: → Update weekly
B21: 📣 CAMPAIGN PERFORMANCE — Pull from Klaviyo → Campaigns (weekly sends only)
B22: Campaign open rate (%) | C22: Klaviyo → Campaigns → latest send | F22: 0.1897 | G22: 0.28 | H22: 0.151 | I22: 0.157 | J22: 0.15 | K22: 0.144 | L22: 0.1512 | M22: 0.542 | Q22: >25% | R22: → Update weekly
B23: Campaign click-through rate (%) | C23: Klaviyo → Campaigns → latest send | F23: 0.0054 | G23: 0.007 | H23: 0.01 | I23: 0.008 | J23: 0.008 | K23: 0.007 | L23: 0.004 | M23: 0.0133 | Q23: >3% | R23: → Update weekly
B24: Campaign revenue (AUD) | C24: Klaviyo → Campaigns → Revenue attributed | F24: 78.11 | G24: N/a | H24: 127 | I24: 606.73 | J24: 350 | K24: 290.31 | L24: 111.42 | M24: 412.32 | Q24: Track trend | R24: → Update weekly
B26: 🎯 PROSPECT SEGMENT — Pull from Klaviyo → Segment: 'Prospects / Never Purchased'
B27: Prospect list size (never purchased) | C27: Klaviyo → Segment → Never Purchased | Q27: Baseline first, then track | R27: → Update weekly
B28: Prospects converted this week | C28: Klaviyo → Segment → Placed first order | Q28: Track toward $85K total | R28: → Update weekly
B29: Prospect CVR this week (%) | C29: Klaviyo calculated | Q29: >3% | R29: → Update weekly
B31: ⚡ INSTANTAI — Automated Flows (welcome · win-back · abandoned cart · post-purchase)
B32: InstantAI flow revenue this week (AUD) | C32: InstantAI dashboard → Overview → Revenue this week | D32: 565.51 | E32: 312.25 | F32: 325.27 | G32: 345.82 | H32: 257.28 | I32: 794.35 | J32: 479.1 | K32: 547.19 | L32: 161.24 | M32: 178.01 | Q32: Track trend — biggest lever
B33: InstantAI flow CVR — all flows combined (%) | C33: InstantAI dashboard → Flows → conversion rate | H33: 0.393 | I33: 0.438 | J33: 46.3 | K33: 44.9 | L33: 42.8 | M33: 40.3 | Q33: Target: >3%
B34: InstantAI abandoned cart recovery rate (%) | C34: InstantAI dashboard → Abandoned Cart flow → recovery rate | D34: 0 | E34: 0 | F34: 0 | G34: 0 | M34: 2 | Q34: Target: >15% (currently ~3.7%)
B35: InstantAI active flows running (count) | C35: InstantAI dashboard → Flows → count of active flows | D35: 12 | E35: 12 | F35: 12 | G35: 12 | H35: 12 | I35: 12 | J35: 12 | K35: 12 | L35: 12 | M35: 12 | Q35: Should be 4: welcome, win-back, cart, post-purchase
B37: 📣 KLAVIYO — Campaign Sends (promotions, product launches, seasonal) — only fill when a campaign was sent
B38: Klaviyo campaign revenue this week (AUD) | C38: Klaviyo → Campaigns → last send → Revenue attributed | Q38: Track per campaign — leave blank if no send
B39: Klaviyo campaign open rate (%) | C39: Klaviyo → Campaigns → last send → Open rate | Q39: Target: >25%
B40: Klaviyo campaign click-through rate (%) | C40: Klaviyo → Campaigns → last send → CTR | Q40: Target: >3%
B41: Klaviyo unsubscribe rate (%) | C41: Klaviyo → Campaigns → last send → Unsubscribe rate | Q41: Target: <0.2% — alert if higher
B43: 📊 COMBINED EMAIL SUMMARY — Auto-calculated from above. Check these numbers in Monday review.
B44: Total email list size (Klaviyo + InstantAI subscribers) | C44: Klaviyo → Audience → All subscribers (source of truth for total list) | Q44: Grow weekly — note new subs from each source
B45: New subscribers added this week (total) | C45: Klaviyo → Growth report → new this week | Q45: Target: +50/week
B47: 📌 NOTE FOR SPECIALIST — How to find InstantAI numbers
...

Sheet 📱 Social Media
B1: Social Media — Weekly KPI Log | 90-Day Sprint
B2: KPI Metric | C2: Data Source | D2: W1 | E2: W2 | F2: W3 | G2: W4 | H2: W5 | I2: W6 | J2: W7 | K2: W8 | L2: W9 | M2: W10 | N2: W11 | O2: W12 | P2: W13 | Q2: 90d Target | R2: Latest Status
B3: 🎵 TIKTOK — Pull from TikTok Business Centre → Analytics
B4: Followers (total) | C4: TikTok Business Centre | D4: 10.8k | E4: 10.8k | F4: 10.8k | G4: 10.8k | H4: 10.8k | I4: 10.8k | J4: 10.8k | K4: 10.8k | L4: 10.8k | M4: 10.8k | Q4: +3,000 by Day 90 | R4: → Update weekly
B5: New followers this week | C5: TikTok Business Centre | D5: 2 | E5: 6 | F5: 8 | G5: 2 | H5: 2 | I5: 1 | J5: 0 | K5: 1 | L5: 2 | M5: 3 | Q5: +230/wk avg | R5: → Update weekly
B6: Total video views this week | C6: TikTok Analytics → Content | D6: 698 | E6: 466 | F6: 494 | G6: 572 | H6: 1182 | I6: 6248 | J6: 677 | K6: 1032 | L6: 2000 | M6: 6400 | Q6: Track trend | R6: → Update weekly
B7: Average views per video | C7: TikTok Analytics → Content | D7: 287 | E7: 644 | F7: 720 | G7: 235 | H7: 634 | I7: 16.4k | J7: 322 | K7: 508 | L7: 474 | M7: 2000 | Q7: >5,000 avg | R7: → Update weekly
B8: Engagement rate (%) | C8: (Likes+Comments+Shares)/Views | D8: 0.0093 | E8: 0.012 | F8: 0.0601 | G8: 3 | H8: 9.99 | I8: 6.2 | J8: 0.0067 | K8: 0.01 | L8: 0.01 | M8: 0.01 | Q8: >4% | R8: → Update weekly
B9: Profile visits from content | C9: TikTok Analytics → Profile | D9: 24 | E9: 66 | F9: 30 | G9: 30 | H9: 21 | I9: 42 | J9: 18 | K9: 47 | L9: 23 | M9: 63 | Q9: Track trend | R9: → Update weekly
B10: Click-through to website | C10: TikTok Analytics → Website clicks | D10: 0 | E10: 3 | F10: 2 | G10: 1 | H10: 0 | I10: 0 | J10: 1 | K10: 0 | L10: 1 | M10: 1 | Q10: Track trend | R10: → Update weekly
B11: Number of videos posted | C11: Manual count | D11: 3 | E11: 3 | F11: 1 | G11: 2 | H11: 3 | I11: 5 | J11: 4 | K11: 2 | L11: 3 | M11: 4 | Q11: 5 per week | R11: → Update weekly
B13: 📸 INSTAGRAM — Pull from Meta Business Suite → Insights
B14: Followers (total) | C14: Meta Business Suite → Audience | D14: 19.8k | E14: 19.8k | F14: 19.7k | G14: 19.7k | H14: 19.7k | I14: 19.7k | J14: 19.7k | K14: 19.7k | L14: 19715 | M14: 19715 | Q14: Track trend | R14: → Update weekly
B15: New followers this week | C15: Meta Business Suite | D15: 16 | E15: 27 | F15: 8 | G15: 14 | H15: 58 | I15: 55 | J15: 46 | K15: 16 | L15: 82 | M15: 15 | Q15: Track trend | R15: → Update weekly
B16: Weekly reach (unique accounts) | C16: Meta Business Suite → Reach | D16: 2k | E16: 1.8k | F16: 1.9k | G16: 1.7k | H16: 871 | I16: 2723 | J16: 4203 | K16: 3k | L16: 11886 | M16: 12932 | Q16: 10,000+/wk | R16: → Update weekly
B17: Weekly impressions | C17: Meta Business Suite → Impressions | Q17: Track trend | R17: → Update weekly
B18: Engagement rate (%) | C18: (Likes+Comments+Saves)/Reach | H18: 0.72 | K18: 0.35 | L18: 0.89 | M18: 0.316 | Q18: >3% | R18: → Update weekly
B19: Story views (weekly total) | C19: Meta Business Suite → Stories | H19: 51 | I19: 206 | J19: 560 | K19: 96 | L19: 29 | M19: 93 | Q19: Track trend | R19: → Update weekly
B20: Reel plays (weekly total) | C20: Meta Business Suite → Reels | K20: 940 | L20: 11k | M20: 900 | Q20: Track trend | R20: → Update weekly
B21: Profile visits | C21: Meta Business Suite → Profile | D21: 80 | E21: 81 | F21: 31 | G21: 45 | H21: 50 | I21: 48 | J21: 96 | K21: 65 | L21: 57 | M21: 59 | Q21: Track trend | R21: → Update weekly
B22: Website clicks from bio/stories | C22: Meta Business Suite → Links | D22: 3 | E22: 3 | F22: 7 | G22: 2 | H22: 2 | I22: 4 | J22: 4 | K22: 2 | L22: 6 | M22: 1 | Q22: Track trend | R22: → Update weekly
B24: 🌐 WEBSITE TRAFFIC — Pull from GA4 → Acquisition → Traffic
B25: Total sessions (week) | C25: GA4 → Reports → Acquisition | D25: 1.1k | E25: 1125 | F25: 1056 | G25: 1131 | H25: 1728 | I25: 5856 | J25: 1808 | K25: 317 | L25: 669 | M25: 988 | Q25: Track trend | R25: → Update weekly
B26: Sessions from organic search | C26: GA4 → Acquisition → Source/Medium | D26: 258 | E26: 213 | F26: 240 | G26: 216 | H26: 131 | I26: 222 | J26: 200 | K26: 50 | L26: 234 | M26: 143 | Q26: Track trend | R26: → Update weekly
B27: Sessions from social (TikTok + IG) | C27: GA4 → Acquisition → Source/Medium | D27: 13 | E27: 17 | F27: 12 | G27: 37 | H27: 4 | I27: 3783 | J27: 18 | K27: 1 | L27: 48 | M27: 43 | Q27: 2,000+/wk | R27: → Update weekly
B28: Sessions from email | C28: GA4 → Acquisition → Source/Medium | D28: 31 | E28: 3 | F28: 98 | G28: 44 | H28: 1128 | I28: 1014 | J28: 835 | K28: 0 | L28: 59 | M28: 33 | Q28: Track trend | R28: → Update weekly
B29: Sessions from paid ads | C29: GA4 → Acquisition → Source/Medium | D29: 249 | E29: 257 | F29: 210 | G29: 207 | H29: 155 | I29: 219 | J29: 113 | K29: 0 | L29: 83 | M29: 144 | Q29: Track vs spend | R29: → Update weekly
B30: Bounce rate (%) | C30: GA4 → Engagement rate (inverse) | D30: 56%% | E30: 0.6178 | F30: 0.4953 | G30: 0.6295 | H30: 0.7662 | I30: 0.689 | J30: 0.746 | K30: 0.82 | L30: 59.71 | M30: 0.58 | Q30: <55% | R30: → Update weekly
B31: Avg session duration (seconds) | C31: GA4 → Engagement | D31: 107.62 | E31: 119.32 | F31: 132.67 | G31: 113.9 | H31: 54.74 | I31: 134.66 | J31: 114 | K31: 25.4 | L31: 44 | M31: 114 | Q31: >90 seconds | R31: → Update weekly
B32: New vs returning visitors — % new | C32: GA4 → User type | D32: 80.9 New | E32: 0.9516 | F32: 0.9502 | G32: 85%% | H32: 0.9242 | I32: 0.9463 | J32: 88.17 | K32: 0.953 | L32: 0.99 | M32: 0.932 | Q32: Track trend | R32: → Update weekly
B34: ✍️ CONTENT OUTPUT — Manual count each week
B35: TikTok videos posted | C35: Manual count | D35: 4 | E35: 2 | F35: 1 | G35: 3 | H35: 3 | I35: 4 | J35: 5 | K35: 3 | L35: 3 | Q35: 5/week | R35: → Update weekly
B36: Instagram feed posts | C36: Manual count | D36: 3 | E36: 4 | F36: 2 | G36: 2 | H36: 1 | I36: 1 | J36: 2 | K36: 4 | L36: 4 | Q36: 3/week | R36: → Update weekly
B37: Instagram stories posted | C37: Manual count | D37: 3 | E37: 4 | F37: 2 | G37: 3 | H37: 3 | I37: 1 | J37: 3 | K37: 5 | L37: 2 | Q37: 5/week | R37: → Update weekly
B38: Substack / blog posts published | C38: Manual count | F38: 1 | G38: 1 | H38: 1 | I38: 1 | J38: 1 | K38: 1 | L38: 1 | Q38: 1/fortnight | R38: → Update weekly
B39: UGC / customer reposts shared | C39: Manual count | J39: 3 | K39: 6 | L39: 3 | Q39: 2+/week | R39: → Update weekly

Sheet 🏥 Clinic Pipeline
B1: Clinic Pipeline — Weekly KPI Log | 90-Day Sprint
B2: KPI Metric | C2: Data Source | D2: W1 | E2: W2 | F2: W3 | G2: W4 | H2: W5 | I2: W6 | J2: W7 | K2: W8 | L2: W9 | M2: W10 | N2: W11 | O2: W12 | P2: W13 | Q2: 90d Target | R2: Latest Status
B3: 🏥 OUTREACH PIPELINE — Manual update from your outreach log each week
B4: Clinics researched / identified (cumulative) | C4: Manual outreach log | Q4: 20+ by W4 | R4: → Update weekly
B5: Outreach sent this week (emails/calls) | C5: Manual outreach log | Q5: 5+/week | R5: → Update weekly
B6: Total outreach sent (cumulative) | C6: Manual outreach log | Q6: 20 by W6 | R6: → Update weekly
B7: Meetings / calls booked this week | C7: Calendar / manual log | Q7: Track conversion | R7: → Update weekly
B8: Clinics closed / signed this week | C8: Manual log | Q8: 5 total by W8 | R8: → Update weekly
B9: Total clinics signed (cumulative) | C9: Manual log | Q9: 5 by Day 60 | R9: → Update weekly
B10: Outreach-to-meeting rate (%) | C10: Meetings booked ÷ outreach sent | Q10: >25% | R10: → Update weekly
B11: Meeting-to-close rate (%) | C11: Closed ÷ meetings held | Q11: >50% | R11: → Update weekly
B13: 💵 CLINIC REVENUE — Pull from Shopify B2B orders or invoices each week
B14: Clinic orders received this week (AUD) | C14: Shopify → Orders tagged Clinic | Q14: $5,000/mo by Day 90 | R14: → Update weekly
B15: Number of active stocking clinics | C15: Manual log | Q15: 5 by Day 60 | R15: → Update weekly
B16: Average order value per clinic (AUD) | C16: Clinic revenue ÷ active clinics | Q16: $1,000/mo per clinic | R16: → Update weekly
B17: Reorder rate — % clinics who reordered | C17: Manual log | Q17: >80% | R17: → Update weekly
B19: 🎓 NATUROPATH EDUCATION — Track engagement with education module
B20: Naturopaths / practitioners contacted | C20: Manual log | Q20: 10+ by W6 | R20: → Update weekly
B21: Education module downloads / views | C21: Google Drive / email tracking | Q21: Track trend | R21: → Update weekly
B22: Practitioners who stocked after education | C22: Manual log | Q22: Track CVR | R22: → Update weekly

Sheet 🌏 Asia Sales
B1: Asia Sales — Weekly KPI Log | 90-Day Sprint
B2: KPI Metric | C2: Data Source | D2: W1 | E2: W2 | F2: W3 | G2: W4 | H2: W5 | I2: W6 | J2: W7 | K2: W8 | L2: W9 | M2: W10 | N2: W11 | O2: W12 | P2: W13 | Q2: 90d Target | R2: Latest Status
B3: 🇨🇳 CHINA — MTD Sales vs Target | Convert CNY → AUD on xe.com before entering
B4: China MTD sales this month (AUD) | C4: WeChat distributor report / Tmall | D4: 5940 | E4: 16456 | F4: 9551 | G4: 50541 | H4: 32510 | I4: 34233 | J4: 32802 | K4: 12144 | L4: 9721 | M4: 15625 | Q4: $3,000 May · Ramps to $6,500 Dec | R4: → Update weekly
B5: Days elapsed in current month | C5: Today's date (e.g. 7 for 7 May) | D5: 8 | E5: 14 | F5: 21 | G5: 29 | H5: 7 | I5: 14 | J5: 22 | K5: 28 | L5: 7 | M5: 14 | Q5: — | R5: → Update weekly
B6: China monthly target (AUD) | C6: Pre-set — only change if target changes | D6: $76,969 | E6: $76,970 | F6: $76,971 | G6: 82488 | H6: 96704 | I6: 96704 | J6: 96704.23 | K6: 64873 | L6: 132016 | M6: 6713 | Q6: See monthly target ramp | R6: → Update weekly
B7: China projected full-month run-rate (AUD) | C7: MTD divided by days elapsed, multiplied by days in month | Q7: Should meet or beat target | R7: → Update weekly
B8: China % of monthly target | C8: Projected run-rate ÷ target | D8: 0.06 | E8: 0.23 | F8: 0.25 | G8: 1.07 | H8: 0.34 | I8: 0.42 | J8: 0.41 | K8: 0.19 | L8: 7%% | M8: 0.23 | Q8: >100% | R8: → Update weekly
B9: China KOLs activated (cumulative) | C9: Manual log | Q9: 3 by Day 60 | R9: → Update weekly
B10: China WeChat followers / community size | C10: WeChat business account | Q10: Track trend | R10: → Update weekly
B12: 🇰🇷 SOUTH KOREA — Baseline tracking | Convert KRW → AUD (1 AUD ≈ 890 KRW)
B13: South Korea monthly sales (AUD) | C13: Distributor report / Shopify filter by KR | D13: $2,593.70 | E13: $1,615.96 | F13: 1825.39 | G13: 2722.43 | H13: A$2,400 | I13: 1805 | J13: 2287 | K13: 2311.5 | L13: 1549 | Q13: Baseline — target set after 3 months | R13: → Update weekly
B14: South Korea MoM change (AUD) | C14: This month minus last month | Q14: Positive trend | R14: → Update weekly
B15: Korea KOLs seeded / activated | C15: Manual log | D15: 11 | Q15: 2 by Day 60 | R15: → Update weekly
B16: Korea distributor meetings held | C16: Manual log | D16: N/A | Q16: 1+ by Day 45 | R16: → Update weekly
B18: 🌏 ASIA COMBINED — Overall L4 Progress
B19: Total Asia revenue this week (AUD) | C19: China + Korea combined | Q19: Foundation phase | R19: → Update weekly
B20: Market assets built — % complete | C20: Manual assessment | Q20: 100% by Day 75 | R20: → Update weekly
B21: Distributor contacts in pipeline | C21: Manual log | Q21: 3+ by Day 45 | R21: → Update weekly
B22: Post-90d revenue pipeline value (AUD) | C22: Deals in discussion — your estimate | Q22: Build pipeline value | R22: → Update weekly

Sheet 💰 Paid Ads
B1: Paid Ads — Weekly KPI Log | 90-Day Sprint
B2: KPI Metric | C2: Data Source | D2: W1 | E2: W2 | F2: W3 | G2: W4 | H2: W5 | I2: W6 | J2: W7 | K2: W8 | L2: W9 | M2: W10 | N2: W11 | O2: W12 | P2: W13 | Q2: 90d Target | R2: Latest Status
B3: 📣 META ADS (Facebook / Instagram) — Pull from Meta Ads Manager each Monday
B4: Meta weekly ad spend (AUD) | C4: Meta Ads Manager → Spend | D4: 245.96 | E4: $210.62 | F4: $169.32 | G4: 173.75 | H4: 103.01 | I4: 172.38 | J4: 174.19 | K4: 152 | L4: 298.15 | M4: 178 | Q4: Track vs budget | R4: → Update weekly
B5: Meta revenue attributed (AUD) | C5: Meta Ads Manager → Purchase value | D5: $398.49 | E5: $602.37 | F5: $358.96 | G5: 56.95 | H5: 179.9 | I5: 231.88 | J5: 535 | K5: 80 | L5: 149.08 | M5: 156 | Q5: ROAS >2.5× | R5: → Update weekly
B6: Meta ROAS (return on ad spend) | C6: Revenue ÷ Spend | D6: 1.62 | E6: 2.86 | F6: 2.12 | G6: 0.33 | H6: 1.75 | I6: 1.35 | J6: 0.3 | K6: 0.52 | L6: 0.46 | M6: 0.15 | Q6: >2.5× | R6: → Update weekly
B7: Meta CPC — cost per click (AUD) | C7: Meta Ads Manager → CPC | D7: 1.55 | E7: 1.19 | F7: 2.14 | G7: 2.09 | H7: 1.91 | I7: 4.93 | J7: 4.84 | K7: 3.39 | L7: 4.45 | M7: 3.64 | Q7: <$1.20 | R7: → Update weekly
B8: Meta CPM — cost per 1,000 impressions | C8: Meta Ads Manager → CPM | D8: 7.75 | E8: 9.43 | F8: 10.28 | G8: 11.03 | H8: 10.43 | I8: 13 | J8: 14.23 | K8: 14.48 | L8: 12.98 | M8: 14.11 | Q8: Track trend | R8: → Update weekly
B9: Meta click-through rate (%) | C9: Meta Ads Manager → CTR | D9: 0.005 | E9: 0.0079 | F9: 0.0048 | G9: 0.0053 | H9: 0.55 | I9: 0.26 | J9: 0.0029 | K9: 0.0043 | L9: 0.0029 | M9: 0.0028 | Q9: >1.5% | R9: → Update weekly
B10: Meta purchases this week | C10: Meta Ads Manager → Conversions | D10: 3 | E10: 4 | F10: 5 | G10: 1 | H10: 2 | I10: 3 | J10: 1 | K10: 2 | L10: 2 | M10: 2 | Q10: Track trend | R10: → Update weekly
B11: Meta cost per purchase / CAC (AUD) | C11: Spend ÷ Purchases | D11: 81.99 | E11: $52.66 | F11: 33.28 | G11: 174 | H11: 51.51 | I11: 57.46 | J11: 174.19 | K11: 79.85 | L11: 149 | M11: 89 | Q11: <$30 | R11: → Update weekly
B13: 🎵 TIKTOK ADS (if running) — Pull from TikTok Ads Manager each Monday
B14: TikTok weekly ad spend (AUD) | C14: TikTok Ads Manager → Spend | D14: 114 | Q14: Track vs budget | R14: → Update weekly
B15: TikTok revenue attributed (AUD) | C15: TikTok Ads Manager → Purchase value | Q15: ROAS >2.5× | R15: → Update weekly
B16: TikTok ROAS | C16: Revenue ÷ Spend | D16: 0 | Q16: >2.5× | R16: → Update weekly
B17: TikTok CPC (AUD) | C17: TikTok Ads Manager → CPC | D17: 0.79 | Q17: <$0.80 | R17: → Update weekly
B18: TikTok video completion rate (%) | C18: TikTok Ads Manager → Video views | Q18: >25% | R18: → Update weekly
B19: TikTok cost per purchase / CAC (AUD) | C19: Spend ÷ Purchases | D19: 14.5 | Q19: <$30 | R19: → Update weekly
B21: 🟢 GOOGLE ADS — Pull from Google Ads Manager (ads.google.com) each Monday
B22: Google Ads weekly spend (AUD) | C22: Google Ads → Campaigns → Spend | D22: 441 | E22: $397.45 | F22: 431.74 | G22: 344.44 | H22: 202 | I22: 399.85 | J22: 399 | K22: 465.61 | L22: 334 | M22: 413.69 | Q22: Track vs budget | R22: → Update weekly
B23: Google Ads revenue attributed (AUD) | C23: Google Ads → Conversions → Conv. value | D23: $1.14k | E23: $451.55 | F23: 464.62 | G23: 785.1 | H23: 560.93 | I23: 652.29 | J23: 983.26 | K23: 823.43 | L23: 750 | M23: 813.73 | Q23: ROAS >3.0× | R23: → Update weekly
B24: Google Ads ROAS | C24: Revenue ÷ Spend | D24: 258.34 | E24: 1.14 | F24: 1.08 | G24: 2.28 | H24: 277.86 | I24: 1.63 | J24: 246.85 | K24: 1.77 | L24: 2.25 | M24: 1.97 | Q24: >3.0× | R24: → Update weekly
B25: Google Ads CPC — cost per click (AUD) | C25: Google Ads → Keywords → Avg CPC | D25: 2.47 | E25: 2.23 | F25: 2.54 | G25: 2.06 | H25: 2.19 | I25: 1.93 | J25: 2.31 | K25: 2.28 | L25: 2.17 | M25: 1.99 | Q25: <$1.50 | R25: → Update weekly
B26: Google Ads CTR — click-through rate (%) | C26: Google Ads → Campaigns → CTR | D26: 0.0112 | E26: 0.0103 | F26: 0.0123 | G26: 0.0173 | H26: 0.0431 | I26: 0.0154 | J26: 0.0126 | K26: 0.0235 | L26: 1.54 | M26: 0.0155 | Q26: >3% | R26: → Update weekly
B27: Google Ads conversions (purchases) | C27: Google Ads → Conversions → Purchases | D27: 12.9 | E27: 7.6 | F27: 9 | G27: 12 | H27: 3 | I27: 11 | J27: 12.85 | K27: 28 | L27: 13 | M27: 15 | Q27: Track trend | R27: → Update weekly
B28: Google Ads CAC — cost per purchase (AUD) | C28: Spend ÷ Purchases | D28: $34.21` | E28: 52.31 | F28: $47.96 | G28: 28.65 | H28: 25.51 | I28: 34.27 | J28: 32 | K28: 16.5 | L28: 25.43 | M28: 28 | Q28: <$30 | R28: → Update weekly
B29: Google Ads Quality Score (avg) | C29: Google Ads → Keywords → Quality Score | D29: 10 | E29: 10 | F29: 8 | G29: 10 | H29: 10 | I29: 10 | J29: 10 | K29: 10 | L29: 10 | M29: 9 | Q29: >6/10 | R29: → Update weekly
B30: 📊 BLENDED ADS SUMMARY — Meta + TikTok + Google combined | C30: Meta + TikTok spend combined | Q30: Track vs budget | R30: → Update weekly
B31: Total ad-attributed revenue (AUD) | C31: Meta + TikTok + Google revenue combined | Q31: ROAS >2.5× | R31: → Update weekly
B32: Blended ROAS | C32: Total revenue ÷ total spend | Q32: >2.5× | R32: → Update weekly
B33: Blended CAC (AUD) | C33: Total spend ÷ total new customers | Q33: <$30 | R33: → Update weekly
B34: Ad spend as % of revenue (%) | C34: Spend ÷ Revenue | Q34: <25% of revenue | R34: → Update weekly

Sheet 📊 Dashboard Summary
B1: SkinB5 Growth 2026 — Weekly KPI Summary | Read this in Monday review
B2: All figures auto-pull from input sheets. GREEN = on track AMBER = watch RED = behind
B4: Metric | C4: This Week (W1) | D4: 90-Day Target | E4: Status | F4: Sheet to update | G4: Action if red
B5: REVENUE (L3 DTC engine)
B6: Weekly revenue (AUD) | C6: ='🛒 Shopify & Revenue'!D5 -> 2467.76 | D6: $5,500/wk by W13 | E6: → Enter data | F6: 🛒 Shopify & Revenue | G6: Check AOV + conversion rate
B7: Average order value (AUD) | C7: ='🛒 Shopify & Revenue'!D8 -> 1855.79 | D7: +15% vs baseline | E7: → Enter data | F7: 🛒 Shopify & Revenue | G7: Add bundles / upsell to cart
B8: Repeat purchase rate (%) | C8: ='🛒 Shopify & Revenue'!D12 -> 19 | D8: >35% | E8: → Enter data | F8: 🛒 Shopify & Revenue | G8: Review win-back flow + loyalty
B9: Customer LTV (AUD) | C9: ='🛒 Shopify & Revenue'!D13 -> 17 | D9: +20% vs baseline | E9: → Enter data | F9: 🛒 Shopify & Revenue | G9: Increase AOV + repeat rate
B10: Store conversion rate (%) | C10: ='🛒 Shopify & Revenue'!D21 -> 0.0177 | D10: >2.5% | E10: → Enter data | F10: 🛒 Shopify & Revenue | G10: Review product pages + UX
B12: EMAIL & FLOWS (L3 DTC)
B13: Welcome flow CVR (%) | C13: ='📧 Email & CRM'!D11 -> 0.195 | D13: >3% | E13: → Enter data | F13: 📧 Email & CRM | G13: Review email sequence copy
B14: Win-back CVR (%) | C14: ='📧 Email & CRM'!D19 | D14: >8% | E14: → Enter data | F14: 📧 Email & CRM | G14: Strengthen offer + urgency
B15: Prospect list converted this week | C15: ='📧 Email & CRM'!D30 | D15: Track vs $85K | E15: → Enter data | F15: 📧 Email & CRM | G15: Check campaign send + CVR
B16: Email list growth (new subs) | C16: ='📧 Email & CRM'!D6 | D16: +50/week | E16: → Enter data | F16: 📧 Email & CRM | G16: Review lead magnet / pop-up
B18: SOCIAL MEDIA (L1 Brand Virality)
B19: TikTok avg video views | C19: ='📱 Social Media'!D7 -> 287 | D19: >5,000 avg | E19: → Enter data | F19: 📱 Social Media | G19: Review hook + posting time
B20: Instagram weekly reach | C20: ='📱 Social Media'!D18 | D20: 10,000+/wk | E20: → Enter data | F20: 📱 Social Media | G20: Boost top posts, use Reels
B21: Sessions from social (GA4) | C21: ='📱 Social Media'!D30 -> 56%% | D21: 2,000+/wk | E21: → Enter data | F21: 📱 Social Media | G21: Add stronger CTA to bio/stories
B22: TikTok engagement rate (%) | C22: ='📱 Social Media'!D9 -> 24 | D22: >4% | E22: → Enter data | F22: 📱 Social Media | G22: Respond to comments, post Q&A
B23: Content output — TikToks posted | C23: ='📱 Social Media'!D36 -> 3 | D23: 5/week | E23: → Enter data | F23: 📱 Social Media | G23: Batch-film content on one day
B25: CLINIC DISTRIBUTION (L2)
B26: Total clinics signed (cumulative) | C26: ='🏥 Clinic Pipeline'!D9 | D26: 5 by Day 60 | E26: → Enter data | F26: 🏥 Clinic Pipeline | G26: Increase outreach volume
B27: Clinic revenue this week (AUD) | C27: ='🏥 Clinic Pipeline'!D14 | D27: $5K/mo by Day 90 | E27: → Enter data | F27: 🏥 Clinic Pipeline | G27: Follow up on reorders
B28: Outreach sent this week | C28: ='🏥 Clinic Pipeline'!D5 | D28: 5+/week | E28: → Enter data | F28: 🏥 Clinic Pipeline | G28: Block time in calendar
B30: ASIA EXPANSION (L4)
B31: China MTD sales (AUD) | C31: ='🌏 Asia Sales'!D5 -> 8 | D31: $3,000 May target | E31: → Enter data | F31: 🌏 Asia Sales | G31: Chase distributor report
B32: China % of monthly target (%) | C32: ='🌏 Asia Sales'!D9 | D32: >100% | E32: → Enter data | F32: 🌏 Asia Sales | G32: Review KOL activity
B33: South Korea monthly sales (AUD) | C33: ='🌏 Asia Sales'!D13 -> $2,593.70 | D33: Baseline tracking | E33: → Enter data | F33: 🌏 Asia Sales | G33: Log distributor figures
B34: KOLs activated (combined) | C34: ='🌏 Asia Sales'!D10 | D34: 5 by Day 60 | E34: → Enter data | F34: 🌏 Asia Sales | G34: Prioritise KOL outreach
B36: PAID ADS
B37: Blended ROAS | C37: ='💰 Paid Ads'!D24 -> 258.34 | D37: >2.5× | E37: → Enter data | F37: 💰 Paid Ads | G37: Pause underperforming ads
B38: Blended CAC (AUD) | C38: ='💰 Paid Ads'!D25 -> 2.47 | D38: <$30 | E38: → Enter data | F38: 💰 Paid Ads | G38: Review audience targeting
B39: Total ad spend this week (AUD) | C39: ='💰 Paid Ads'!D23 -> $1.14k | D39: Track vs budget | E39: → Enter data | F39: 💰 Paid Ads | G39: Reallocate to best ROAS channel

Sheet ✍️ Substack
B1: ✍️ Substack — The Inside-Out Letter | Weekly KPI Log | Launched 26 May 2026 (W1 = week of 26 May)
B2: 🔵 Blue cells = your input | W1 = week starting 26 May 2026 | Source: Substack dashboard + Klaviyo + social platforms | Note: launched 1 week later than original plan
B4: KPI Metric | C4: Data Source | D4: W1 | E4: W2 | F4: W3 | G4: W4 | H4: W5 | I4: W6 | J4: W7 | K4: W8 | L4: W9 | M4: W10 | N4: W11 | O4: W12 | P4: W13 | Q4: 90-Day Target
B5: 📈 LEADING INDICATORS — Update every Monday from Substack dashboard
B6: Total Substack subscribers | C6: Substack dashboard → Stats | D6: 1 | E6: 1 | F6: 2 | G6: 3 | H6: 3 | I6: 3 | J6: 2 | Q6: 800–2,000 by Day 90
B7: New subscribers this week | C7: Substack dashboard → Stats → New this week | D7: 1 | E7: 1 | F7: 0 | G7: 1 | H7: 0 | I7: 0 | J7: 0 | Q7: +60/wk by W12
B8: Posts published this week | C8: Manual count (should be 1/wk Tuesday 7am AEST) | D8: 1 | E8: 1 | F8: 1 | G8: 1 | H8: 1 | I8: 1 | J8: 1 | Q8: 1 per week
B9: Post open rate (%) | C9: Substack dashboard → latest post → Open rate | D9: 1 | E9: 100 | F9: 15.7 | G9: N/A | H9: 1 | J9: 1 | Q9: ≥45%
B10: TikTok atoms shipped (videos from post) | C10: Manual count — TikToks posted from each Substack post | D10: 0 | E10: 2 | F10: 0 | G10: 1 | H10: 1 | I10: 1 | J10: 1 | Q10: 3 per week
B11: IG carousel saves (per post) | C11: Meta Business Suite → latest IG carousel post → Saves | D11: 1 | F11: 0 | G11: 1 | H11: 1 | I11: 1 | J11: 1 | Q11: ≥80 saves/post
B12: Reader replies (email + DMs to Judy) | C12: Manual count — replies received after each post | D12: 0 | E12: 0 | F12: 0 | G12: 0 | H12: 0 | I12: 0 | J12: 0 | Q12: ≥20/week
B14: 💬 ENGAGEMENT INDICATORS — Update monthly (first Monday of each month)
B15: Average open rate last 4 posts (%) | C15: Substack → Stats → average of last 4 posts | D15: 1 | E15: 100 | Q15: ≥45%
B16: Anonymous Q&A submissions this month | C16: Substack chat / typeform / email anon box | D16: 0 | E16: 0 | Q16: ≥40/month
B17: Founding Readers signed (cumulative) | C17: Manual count — loyalty customers who joined Substack | D17: 0 | E17: 0 | Q17: 100 by W12
B18: Reader of Month features published | C18: Manual count — 1 per month target | D18: 0 | E18: 0 | Q18: 3 by W12 (1/mo)
B20: 💰 BUSINESS INDICATORS — Track revenue via unique subscriber code + UTM parameters
B21: Substack total subscribers → 1st purchase CVR (%) | C21: Shopify → UTM source=substack OR subscriber code used | D21: 0 | E21: 0 | Q21: 6–8% CVR
B22: Substack direct revenue (AUD) — cumulative | C22: Shopify → filter by subscriber discount code OR substack UTM | D22: 0 | E22: 0 | Q22: $5K–$15K by Day 90
B23: Substack-acquired repeat purchase rate (%) | C23: Shopify → customers acquired via Substack → repeat rate | D23: 0 | E23: 0 | Q23: ≥45%
B24: Estimated halo revenue (2–3× direct) | C24: Manual estimate: direct revenue × 2.5 | D24: 0 | E24: 0 | Q24: $15K–$45K total
B25: New 1st-time customers from subscriber code | C25: Shopify → discount code report → new customers only | D25: 0 | E25: 0 | Q25: 48–144 by Day 90
B27: 🔁 CROSS-PROMO CONTENT OUTPUT — Each Substack post should produce these atoms
B28: TikTok videos posted from this post | C28: Manual count — from Block 1 hook + Block 3 BS Watch | D28: 0 | E28: 1 | Q28: 3/week (from each post)
B29: IG carousel posts from this post | C29: Manual count — from Block 2 Science section | D29: 1 | E29: 1 | Q29: 1/week
B30: IG story polls from this post | C30: Manual count — from Block 6 Reader Question | D30: 1 | E30: 1 | Q30: 1/week
B31: Email digest sent (Thursday Klaviyo) | C31: Klaviyo → Campaigns → Thursday digest | D31: 1 | E31: 1 | Q31: 1/week
B33: 📅 12-WEEK POST CALENDAR — Shifted 1 week (launch 26 May, not 19 May as planned)
B34: Week / Date | C34: Post title | D34: Content notes | E34: Status
B35: W1 — 26 May 2026 | C35: I had acne for years and tried everything. Then I made my own vitamin. | D35: Founder origin · Lead with possibility not pain · Add Field Notes | E35: Keep+
B36: W2 — 2 Jun 2026 | C36: The Medik8 recall & the SPF industry's dirty little secret. | D36: BS Watch framing · Strongest post · TikTok: 60s rant | E36: Keep
B37: W3 — 9 Jun 2026 | C37: Your acne is a symptom, not a problem. | D37: 4-step story · Pathway diagram carousel | E37: Keep
B38: W4 — 16 Jun 2026 | C38: The 6 foods I eat every week (and the 3 I quietly stopped). | D38: Add community naming poll · Kitchen photos | E38: Keep+
B39: W5 — 23 Jun 2026 | C39: Why my skincare company started in a forest, not a lab. | D39: Naturalist worldview · Wellness-first philosophy · WRITE FIRST | E39: NEW
B40: W6 — 30 Jun 2026 | C40: Beauty BS Watch: how to read a supplement label. | D40: Launch recurring BS Watch series | E40: Reframe
B41: W7 — 7 Jul 2026 | C41: The gut-skin axis. | D41: 60s gut-skin TikTok · Gut foods carousel | E41: Keep
B42: W8 — 14 Jul 2026 | C42: Reader Q&A: hormonal acne, adult breakouts. | D42: Monthly recurring last Tuesday · 3 Q&A TikTok clips | E42: Keep+
B43: W9 — 21 Jul 2026 | C43: The Inside-Out Skin Reset: 30-day protocol. | D43: Biggest lead magnet · PDF download · Subscriber-only price | E43: Keep+
B44: W10 — 28 Jul 2026 | C44: Hormonal acne in your 30s & 40s. | D44: Cycle & skin carousel · Subscription model code | E44: Keep
B45: W11 — 4 Aug 2026 | C45: The peptide problem & what to take instead. | D45: Debunk · Ingredient comparison · Pre-launch interest list | E45: Replace
...
